Workbook

Sheet Guidance
A1: Contents
A2: BFI and Film4 Future Takes: Production Budget - Guidance
A3: Please read the guidance below in full while putting together an application to BFI and Film4 Future Takes.
A4: Contents
E6: Information & Finance Plan | G6: =A41 -> Budget Breakdown | I6: =A87 -> Access Budget
E7: =D24 -> Project & Team Information | G7: =D46 -> Completing the budget | I7: =D92 -> Updating the access budget
E8: =D31 -> Finance Plan | G8: =D50 -> Additional support | I8: =D96 -> Example costs
E9: =D35 -> In kind support | G9: =D55 -> London Living Wage
G10: =D59 -> Student Placements
G11: =D64 -> Above the line / core team fees
G12: =D67 -> Flat rates
G13: =D71 -> Deliverables
G14: =D75 -> Legal Fees
G15: =D79 -> Insurance
G16: =D82 -> Contingency
A19: Information & Finance Plan
C21: In this section of the Production Budget producers should add information on their proposed production schedule, the names of the core creative team members and the finance plan for the project. Any additional finance and in kind support that has been offered or is planned to be secured should also be included.
D24: Project & Team Information
E25: ▪ Project Title | I25: ▪ Length of project preparation | XX weeks
E26: ▪ Production Company | I26: ▪ Length of shoot | X days
E27: ▪ Producer(s) name | I27: ▪ Length of shooting days | X hours
E28: ▪ Writer(s) name | I28: ▪ Shooting format | Digital, 35mm film or other formats
E29: ▪ Director(s) name
D31: Finance Plan
E32: Award request amount | The total amount being applied for
E33: Any other sources of income | Your project should be fully funded through Future Takes. We will not support projects where the budget exceeds what you are requesting from us (unless you plan to use your own private funds). This may include private equity or investments. Producers do not have to raise additional finance for their project, if it can be made with the amount of funding requested from BFI and Film4 Future Takes. Any contribution of less than £50 should be credited to the contingency of the project.
D35: In kind support
E36: Applicants may find that some kit or post-production houses with whom they have an existing professional relationship will be willing to provide services in kind. We can only allow in-kind work from companies who will be paying their staff directly - individual freelancers cannot work on a BFI and Film4 Future Takes funded film without payment.
E37: Add the organisation/company name and the total amount of the support provided in the finance section of the sheet. Applicants still need to complete the corresponding line on the budget with a cost of £0 and add 'in kind support' in the Notes column for reference.
A41: Budget Breakdown
C43: In this section applicants need to detail all of the costs that they would need to budget for to deliver their project. Producers are not required to put a cost against every line of the budget template – not all cost types will be relevant to a project – and this should only show the expenditure that is actually expected to be incurred.
D46: Completing the budget
E47: Enter information into the yellow cells on the Production Budget tab and the sheet will calculate out the totals. There is space next to every budget line to add notes, this can be information on support in kind, higher than average predicted costs or anything else relevant to include.
E48: There is a breakdown of what the BFI require within the budget in section 4. What you can use the funding for in the funding guidelines.
D50: Additional support
E51: Applicants can get help if they need support to apply for funding. They might need support because they are disabled, neurodivergent or another reason. We work with TAPE Community Film and Music to provide access support. TAPE is an award-winning, community arts charity based in North Wales
E52: Get access support to apply for BFI funds | https://www.bfi.org.uk/get-funding-support/get-access-support-apply-bfi-funds
D55: London Living Wage
E56: All cast and crew involved in the making of a BFI and Film4 Future Takes funded film must be paid at least equivalent to the London Living Wage. Crew fees should have parity across departments. This means that we expect crew members at a similar experience level to be paid the same across the production, for example a Production Assistant would be paid the same as a Camera Assistant. We want to ensure that everyone who works on BFI nd Film4 Future Takes funded productions are paid for their time.
E57: Current Hourly Rate | https://www.london.gov.uk/programmes-strategies/business-and-economy/london-living-wage/
...

Sheet Production Budget
B1: BFI and Film4 Future Takes Budget Template
B3: Project & Team Information | F3: Budget Breakdown | M3: Cost reporting
B4: Project title: | F4: Line No. | G4: Description | H4: Amounts | I4: Unit | J4: Rate (£) | K4: Subtotal | L4: Notes | M4: Actual | N4: Variance | O4: Notes
F5: Example: | H5: 5 | I5: Days | J5: 500 | K5: =H5*J5 -> 2500
B6: Production company: | F6: 1 | G6: Story and script
F7: 1.1 | G7: Writers fee | K7: =J7*H7 -> 0 | N7: =K7-M7 -> 0
B8: Producer(s): | F8: 1.2 | G8: Story rights/options | K8: =J8*H8 -> 0 | N8: =K8-M8 -> 0
B10: Writer(s): | F10: Subtotal: | K10: =SUM(K7:K9) -> 0 | M10: =SUM(M7:M9) -> 0 | N10: =SUM(N7:N9) -> 0
F11: 2 | G11: Producer
B12: Director(s): | F12: 2.1 | G12: Producer fee | K12: =H12*J12 -> 0 | N12: =K12-M12 -> 0
F13: 2.2 | G13: Executive Producers Fee | K13: =H13*J13 -> 0 | N13: =K13-M13 -> 0
B14: Length of preperation:
F15: Subtotal: | K15: =SUM(K12:K14) -> 0 | M15: =SUM(M12:M14) -> 0 | N15: =SUM(N12:N14) -> 0
B16: Length of shoot: | F16: 3 | G16: Director
F17: 3.1 | G17: Director fee | K17: =H17*J17 -> 0 | N17: =K17-M17 -> 0
B18: Length of shoot day:
F19: Subtotal: | K19: =SUM(K17:K18) -> 0 | M19: =SUM(M17:M18) -> 0 | N19: =SUM(N17:N18) -> 0
B20: Shoot format: | F20: Total above the line: | L20: =K10+K15+K19 -> 0 | M20: =SUM(M10,M15,M19) -> 0 | N20: =SUM(N19,N10,N15) -> 0
B22: Finance Plan | F22: 4 | G22: Cast
B23: Source | C23: Amount (£) | D23: Secured | F23: 4.1 | G23: Casting director | K23: =H23*J23 -> 0 | N23: =K23-M23 -> 0
B24: Award Request Amount | F24: 4.2 | G24: Lead cast
F25: 4.2.1 | G25: Lead actor / Voice over artist | K25: =H25*J25 -> 0 | N25: =K25-M25 -> 0
B26: [e.g. Private investment] | D26: [yes/no] | F26: 4.2.2 | G26: Lead actor 2 | K26: =H26*J26 -> 0 | N26: =K26-M26 -> 0
F27: 4.2.3 | G27: Lead actor 3 | K27: =H27*J27 -> 0 | N27: =K27-M27 -> 0
D28: [yes/no] | F28: 4.3 | G28: Supporting cast
F29: 4.3.1 | G29: Supporting actor 1 | K29: =H29*J29 -> 0 | N29: =K29-M29 -> 0
C30: 0 | D30: [yes/no] | F30: 4.3.2 | G30: Supporting actor 2 | K30: =H30*J30 -> 0 | N30: =K30-M30 -> 0
F31: 4.3.3 | G31: Supporting actor 3 | K31: =H31*J31 -> 0 | N31: =K31-M31 -> 0
C32: 0 | D32: [yes/no] | F32: 4.4 | G32: Extras
F33: 4.4.1 | G33: Scene number: | K33: =H33*J33 -> 0 | N33: =K33-M33 -> 0
B34: Total finance plan | C34: =SUM(C24:C33) -> 0 | F34: 4.4.2 | G34: Scene number: | K34: =H34*J34 -> 0 | N34: =K34-M34 -> 0
F35: 4.4.3 | G35: Scene number: | K35: =H35*J35 -> 0 | N35: =K35-M35 -> 0
B36: Total project budget | C36: =J214 -> 0 | F36: 4.5 | G36: Stunt coordinator | K36: =H36*J36 -> 0 | N36: =K36-M36 -> 0
F37: 4.6 | G37: Dialogue coach | K37: =H37*J37 -> 0 | N37: =K37-M37 -> 0
B38: Budget surplus/deficit | C38: =-(C36-C34) -> 0 | F38: 4.7 | G38: Chaperone | K38: =H38*J38 -> 0 | N38: =K38-M38 -> 0
B40: In kind support | F40: Subtotal: | K40: =SUM(K23:K39) -> 0 | M40: =SUM(M23:M39) -> 0 | N40: =SUM(N23:N39) -> 0
B41: Source | C41: Amount (£) | D41: Secured | F41: 5 | G41: Production
B42: [Organisation Name] | C42: 0 | D42: [yes/no] | F42: 5.1 | G42: Line producer | K42: =H42*J42 -> 0 | N42: =K42-M42 -> 0
F43: 5.2 | G43: Production manager | K43: =H43*J43 -> 0 | N43: =K43-M43 -> 0
C44: 0 | D44: [yes/no] | F44: 5.3 | G44: Production coordinator | K44: =H44*J44 -> 0 | N44: =K44-M44 -> 0
...

Sheet Access Budget
B1: BFI and Film4 Future Takes: Access Budget
B2: Budget Breakdown | I2: Cost reporting
B3: Line No. | C3: Description | D3: Amounts | E3: Unit | F3: Rate (£) | G3: Subtotal | H3: Notes | I3: Actual | J3: Variance | K3: Notes
B4: Example: | D4: 5 | E4: Days | F4: 500 | G4: =D4*F4 -> 2500
C5: General Access Costs
G6: =F6*D6 -> 0 | J6: =G6-I6 -> 0
G7: =F7*D7 -> 0 | J7: =G7-I7 -> 0
G8: =F8*D8 -> 0 | J8: =G8-I8 -> 0
G9: =F9*D9 -> 0 | J9: =G9-I9 -> 0
G10: =F10*D10 -> 0 | J10: =G10-I10 -> 0
G11: =F11*D11 -> 0 | J11: =G11-I11 -> 0
G12: =F12*D12 -> 0 | J12: =G12-I12 -> 0
G13: =F13*D13 -> 0 | J13: =G13-I13 -> 0
G14: =F14*D14 -> 0 | J14: =G14-I14 -> 0
G15: =F15*D15 -> 0 | J15: =G15-I15 -> 0
B17: Subtotal: | G17: =SUM(G6:G16) -> 0 | I17: =SUM(I6:I16) -> 0 | J17: =SUM(J6:J16) -> 0
B18: Total general access costs: | H18: =G17 -> 0 | I18: =SUM(I9:I16) -> 0 | J18: =SUM(J17) -> 0
B20: 4 | C20: Cast
B21: 4.1 | C21: Casting director | G21: =D21*F21 -> 0 | J21: =G21-I21 -> 0
B22: 4.2 | C22: Lead cast
B23: 4.2.1 | C23: Lead actor / Voice over artist | G23: =D23*F23 -> 0 | J23: =G23-I23 -> 0
B24: 4.2.2 | C24: Lead actor 2 | G24: =D24*F24 -> 0 | J24: =G24-I24 -> 0
B25: 4.2.3 | C25: Lead actor 3 | G25: =D25*F25 -> 0 | J25: =G25-I25 -> 0
B26: 4.3 | C26: Supporting cast
B27: 4.3.1 | C27: Supporting actor 1 | G27: =D27*F27 -> 0 | J27: =G27-I27 -> 0
B28: 4.3.2 | C28: Supporting actor 2 | G28: =D28*F28 -> 0 | J28: =G28-I28 -> 0
B29: 4.3.3 | C29: Supporting actor 3 | G29: =D29*F29 -> 0 | J29: =G29-I29 -> 0
B30: 4.4 | C30: Extras
B31: 4.4.1 | C31: Scene number: | G31: =D31*F31 -> 0 | J31: =G31-I31 -> 0
B32: 4.4.2 | C32: Scene number: | G32: =D32*F32 -> 0 | J32: =G32-I32 -> 0
B33: 4.4.3 | C33: Scene number: | G33: =D33*F33 -> 0 | J33: =G33-I33 -> 0
B34: 4.5 | C34: Stunt coordinator | G34: =D34*F34 -> 0 | J34: =G34-I34 -> 0
B35: 4.6 | C35: Dialogue coach | G35: =D35*F35 -> 0 | J35: =G35-I35 -> 0
B36: 4.7 | C36: Chaperone | G36: =D36*F36 -> 0 | J36: =G36-I36 -> 0
B38: Subtotal: | G38: =SUM(G21:G37) -> 0 | I38: =SUM(I21:I37) -> 0 | J38: =SUM(J21:J37) -> 0
B39: 5 | C39: Production
B40: 5.1 | C40: Line producer | G40: =D40*F40 -> 0 | J40: =G40-I40 -> 0
B41: 5.2 | C41: Production manager | G41: =D41*F41 -> 0 | J41: =G41-I41 -> 0
B42: 5.3 | C42: Production coordinator | G42: =D42*F42 -> 0 | J42: =G42-I42 -> 0
B43: 5.4 | C43: Production assistant | G43: =D43*F43 -> 0 | J43: =G43-I43 -> 0
...

Sheet Top Sheet
B1: BFI NETWORK England Short Film Fund: Production Budget Top Sheet
B2: ='Production Budget'!B4 -> Project title: | C2: ='Production Budget'!C4 -> 0 | F2: ='Production Budget'!F3 -> Budget Breakdown | I2: ='Production Budget'!M3 -> Cost reporting
F3: ='Production Budget'!F4 -> Line No. | G3: ='Production Budget'!G4 -> Description | H3: ='Production Budget'!K4 -> Subtotal | I3: ='Production Budget'!M4 -> Actual | J3: ='Production Budget'!N4 -> Variance
F4: ='Production Budget'!F6 -> 1 | G4: ='Production Budget'!G6 -> Story and script | H4: ='Production Budget'!K10 -> 0 | I4: ='Production Budget'!M10 -> 0 | J4: ='Production Budget'!N10 -> 0
B5: ='Production Budget'!B22 -> Finance Plan | F5: ='Production Budget'!F11 -> 2 | G5: ='Production Budget'!G11 -> Producer | H5: ='Production Budget'!K15 -> 0 | I5: ='Production Budget'!M15 -> 0 | J5: ='Production Budget'!N15 -> 0
B6: ='Production Budget'!B23 -> Source | C6: ='Production Budget'!C23 -> Amount (£) | D6: ='Production Budget'!D23 -> Secured | F6: ='Production Budget'!F16 -> 3 | G6: ='Production Budget'!G16 -> Director | H6: ='Production Budget'!K19 -> 0 | I6: ='Production Budget'!M19 -> 0 | J6: ='Production Budget'!N19 -> 0
B7: ='Production Budget'!B24 -> Award Request Amount | C7: ='Production Budget'!C24 -> 0 | F7: ='Production Budget'!F20 -> Total above the line: | H7: =SUM(H4:H6) -> 0 | I7: =SUM(I4:I6) -> 0 | J7: =SUM(J4:J6) -> 0
B8: ='Production Budget'!B26 -> [e.g. Private investment] | C8: ='Production Budget'!C26 -> 0 | D8: ='Production Budget'!D26 -> [yes/no] | F8: ='Production Budget'!F22 -> 4 | G8: ='Production Budget'!G22 -> Cast | H8: ='Production Budget'!K40 -> 0 | I8: ='Production Budget'!M40 -> 0 | J8: ='Production Budget'!N40 -> 0
B9: ='Production Budget'!B28 -> 0 | C9: ='Production Budget'!C28 -> 0 | D9: ='Production Budget'!D28 -> [yes/no] | F9: ='Production Budget'!F41 -> 5 | G9: ='Production Budget'!G41 -> Production | H9: ='Production Budget'!K50 -> 0 | I9: ='Production Budget'!M50 -> 0 | J9: ='Production Budget'!N50 -> 0
B10: ='Production Budget'!B30 -> 0 | C10: ='Production Budget'!C30 -> 0 | D10: ='Production Budget'!D30 -> [yes/no] | F10: ='Production Budget'!#REF! -> #REF! | G10: ='Production Budget'!#REF! -> #REF! | H10: ='Production Budget'!#REF! -> #REF! | I10: ='Production Budget'!#REF! -> #REF! | J10: ='Production Budget'!#REF! -> #REF!
B11: ='Production Budget'!B32 -> 0 | C11: ='Production Budget'!C32 -> 0 | D11: ='Production Budget'!D32 -> [yes/no] | F11: ='Production Budget'!#REF! -> #REF! | G11: ='Production Budget'!#REF! -> #REF! | H11: ='Production Budget'!#REF! -> #REF! | I11: ='Production Budget'!#REF! -> #REF! | J11: ='Production Budget'!#REF! -> #REF!
B12: ='Production Budget'!B34 -> Total finance plan | C12: ='Production Budget'!C34 -> 0 | F12: ='Production Budget'!F51 -> 6 | G12: ='Production Budget'!G51 -> Assistant Directors | H12: ='Production Budget'!K58 -> 0 | I12: ='Production Budget'!M58 -> 0 | J12: ='Production Budget'!N58 -> 0
B13: ='Production Budget'!B36 -> Total project budget | C13: ='Production Budget'!C36 -> 0 | F13: ='Production Budget'!F59 -> 7 | G13: ='Production Budget'!G59 -> Camera | H13: ='Production Budget'!K68 -> 0 | I13: ='Production Budget'!M68 -> 0 | J13: ='Production Budget'!N68 -> 0
B14: ='Production Budget'!B38 -> Budget surplus/deficit | C14: ='Production Budget'!C38 -> 0 | F14: ='Production Budget'!F69 -> 8 | G14: ='Production Budget'!G69 -> Lighting | H14: ='Production Budget'!K79 -> 0 | I14: ='Production Budget'!M79 -> 0 | J14: ='Production Budget'!N79 -> 0
B15: ='Production Budget'!B40 -> In kind support | F15: ='Production Budget'!F80 -> 9 | G15: ='Production Budget'!G80 -> Sound | H15: ='Production Budget'!K86 -> 0 | I15: ='Production Budget'!M86 -> 0 | J15: ='Production Budget'!N86 -> 0
B16: ='Production Budget'!B41 -> Source | C16: ='Production Budget'!C41 -> Amount (£) | D16: ='Production Budget'!D41 -> Secured | F16: ='Production Budget'!F87 -> 10 | G16: ='Production Budget'!G87 -> Production design | H16: ='Production Budget'!K102 -> 0 | I16: ='Production Budget'!M102 -> 0 | J16: ='Production Budget'!N102 -> 0
B17: ='Production Budget'!B42 -> [Organisation Name] | C17: ='Production Budget'!C42 -> 0 | D17: ='Production Budget'!D42 -> [yes/no] | F17: ='Production Budget'!F103 -> 11 | G17: ='Production Budget'!G103 -> Costume | H17: ='Production Budget'!K108 -> 0 | I17: ='Production Budget'!M108 -> 0 | J17: ='Production Budget'!N108 -> 0
B18: ='Production Budget'!B44 -> 0 | C18: ='Production Budget'!C44 -> 0 | D18: ='Production Budget'!D44 -> [yes/no] | F18: ='Production Budget'!F109 -> 12 | G18: ='Production Budget'!G109 -> Hair and make up | H18: ='Production Budget'!K117 -> 0 | I18: ='Production Budget'!M117 -> 0 | J18: ='Production Budget'!N117 -> 0
B19: ='Production Budget'!B46 -> 0 | C19: ='Production Budget'!C46 -> 0 | D19: ='Production Budget'!D46 -> [yes/no] | F19: ='Production Budget'!F118 -> 13 | G19: ='Production Budget'!G118 -> Locations | H19: ='Production Budget'!K131 -> 0 | I19: ='Production Budget'!M131 -> 0 | J19: ='Production Budget'!N131 -> 0
B20: Total in kind support | C20: ='Production Budget'!C48 -> 0 | F20: ='Production Budget'!F132 -> 14 | G20: ='Production Budget'!G132 -> Travel and transport | H20: ='Production Budget'!K144 -> 0 | I20: ='Production Budget'!M144 -> 0 | J20: ='Production Budget'!N144 -> 0
F21: ='Production Budget'!F145 -> 15 | G21: ='Production Budget'!G145 -> Accomodation | H21: ='Production Budget'!K150 -> 0 | I21: ='Production Budget'!M150 -> 0 | J21: ='Production Budget'!N150 -> 0
F22: ='Production Budget'!F151 -> 16 | G22: ='Production Budget'!G151 -> Post picture | H22: ='Production Budget'!K164 -> 0 | I22: ='Production Budget'!M164 -> 0 | J22: ='Production Budget'!N164 -> 0
F23: ='Production Budget'!F165 -> 17 | G23: ='Production Budget'!G165 -> Post sound | H23: ='Production Budget'!K172 -> 0 | I23: ='Production Budget'!M172 -> 0 | J23: ='Production Budget'!N172 -> 0
F24: ='Production Budget'!F173 -> 18 | G24: ='Production Budget'!G173 -> Music | H24: ='Production Budget'!K178 -> 0 | I24: ='Production Budget'!M178 -> 0 | J24: ='Production Budget'!N178 -> 0
F25: ='Production Budget'!F179 -> 19 | G25: ='Production Budget'!G179 -> Publicity | H25: ='Production Budget'!K186 -> 0 | I25: ='Production Budget'!M186 -> 0 | J25: ='Production Budget'!N186 -> 0
F26: ='Production Budget'!F187 -> 20 | G26: ='Production Budget'!G187 -> Miscellaneous | H26: ='Production Budget'!K200 -> 0 | I26: ='Production Budget'!M200 -> 0 | J26: ='Production Budget'!N200 -> 0
F27: ='Production Budget'!F201 -> Total below the line: | H27: =SUM(H8:H26) -> #REF! | I27: =SUM(I8:I26) -> #REF! | J27: =SUM(J8:J26) -> #REF!
F28: ='Production Budget'!F203 -> 21 | G28: ='Production Budget'!G203 -> Insurance | H28: ='Production Budget'!K206 -> 0 | I28: ='Production Budget'!M206 -> 0 | J28: ='Production Budget'!N206 -> 0
F29: ='Production Budget'!F207 -> 22 | G29: ='Production Budget'!G207 -> Contingency | H29: ='Production Budget'!K210 -> 0 | I29: ='Production Budget'!M210 -> 0 | J29: ='Production Budget'!N210 -> 0
F30: ='Production Budget'!F211 -> Total other: | H30: =SUM(H28:H29) -> 0 | I30: =SUM(I28:I29) -> 0 | J30: =SUM(J28:J29) -> 0
F32: Budget Total: | I32: =SUM(H30,H27,H7) -> #REF!
F33: Total Costs: | I33: =I30+I27+I7 -> #REF!
F34: Final Variance: | I34: =J30+J27+J7 -> #REF!
